Workbook
Name NativeTimeline_Fecha_clasificacion: #N/A
Name SegmentaciónDeDatos_Clasificacion: #N/A
Name SegmentaciónDeDatos_Fallecido: #N/A
Name SegmentaciónDeDatos_Genero: #N/A
Name SegmentaciónDeDatos_Provincia: #N/A
Name SegmentaciónDeDatos_Tipo_de_contagio: #N/A

Sheet Dashboard
A1: Casos de COVID-19 en la Ciudad de Buenos Aires | N1: Filtros

Sheet Documentación
A1: Proyecto final: Casos de COVID-19 en la Ciudad de Buenos Aires
A3: Autor: Ramiro Nicolas Moreno
A5: Objetivo general:
A7: El proyecto tiene como objetivo analizar los datos de COVID-19 registrados en la Ciudad de Buenos Aires. Este dataset proporciona información detallada sobre los contagios, incluyendo variables como edad, género, fecha de diagnóstico, y lugar de residencia, entre otros. Con el fin de identificar patrones relacionados con la distribución geográfica, demográfica y temporal de los contagios.
A8: Este análisis permite comprender mejor las características de los contagios y proporcionar información clave para la toma de decisiones en la gestión de la pandemia y la implementación de medidas preventivas.
A10: Preguntas claves del análisis:
A11: 1 - Qué provincia tuvo más casos confirmados? Qué provincia tuvo más fallecidos?
A12: 2 - Cuál es la tasa de letalidad por provincia?
A13: 3 - Cuántos fallecidos hubo por provincia? Cuántos casos confirmados, descartados y sospechoso hubo por provincia? Cómo se dividen por sexo?
A14: 4 - Cuántos fallecidos hubo en total? Cuántos casos confirmados en total?
A15: 5 - Qué provincia tuvo más casos confirmados? Qué provincia tuvo más fallecidos?
A16: 6 - Cómo evolucionaron los casos confirmados y fallecimientos a lo largo del tiempo?
... A31: 4 - En caso de realizar futuras agregados de tipos de casos, los gráficos en el dashboard permiten visualizar las métricas de los mismos. Con esto se podrán aplicar distintas medidas estratégicas para reducir los contagios.

Sheet Storytelling
A1: Casos de COVID-19 en la Ciudad de Buenos Aires
A4: Objetivo e introducción:
A6: El proyecto tiene como objetivo analizar los datos de COVID-19 registrados en la Ciudad de Buenos Aires. Este dataset proporciona información detallada sobre los contagios, incluyendo variables como edad, género, fecha de diagnóstico, y lugar de residencia, entre otros. Con el fin de identificar patrones relacionados con la distribución geográfica, demográfica y temporal de los contagios.
A7: Este análisis permite comprender mejor las características de los contagios y proporcionar información clave para la toma de decisiones en la gestión de la pandemia y la implementación de medidas preventivas.
A9: Base de datos, alcance y aplicación:
A10: El proyecto abarca el diseño y la implementación de una base de datos relacional que almacena información sobre los casos de COVID-19, incluyendo detalles sobre el paciente, la ubicación, el tipo de contagio y la clasificación del caso.
A12: Alcance: Está dirigido a gestores de salud pública, analistas de datos, autoridades gubernamentales y académicos. O bien, todo aquel que quisiera investigar datos almacenados sobre los contagios de COVID-19 en la Ciudad Autónoma de Buenos Aires.
A14: Aplicación: El objetivo es proporcionar información a analistas para que monitoreen las operaciones/casos en tiempo real, y además se utilizará para decisiones operativas en la distribución de recursos y para generar estrategias a largo plazo en la gestión de la salud pública.

Sheet Preguntas + formulas
A1: Preguntas | D1: B) | I1: E) | J1: F)
A2: A) | B2: Qué provincia tuvo mas casos confirmados? Que provincia tuvo mas fallecidos? | D2: Provincia | E2: Cantidad de casos confirmados | F2: Cantidad de casos descartados | G2: Cantidad de casos sospechosos | H2: Cantidad de fallecidos | I2: Letalidad en % | J2: Cantidad de casos no peligrosos
A3: B) | B3: Cuántos fallecidos hubo por provincia? Cuántos casos confirmados, descartados y sospechosos hubo por provincia? | D3: Buenos Aires | E3: =COUNTIFS('Dataset - Casos covid 19'!I:I,"confirmado",'Dataset - Casos covid 19'!D:D,"Buenos Aires") -> 511 | F3: =COUNTIFS('Dataset - Casos covid 19'!I:I,"descartado",'Dataset - Casos covid 19'!D:D,"Buenos Aires") -> 156 | G3: =COUNTIFS('Dataset - Casos covid 19'!I:I,"sospechoso",'Dataset - Casos covid 19'!D:D,"Buenos Aires") -> 15 | H3: =COUNTIFS('Dataset - Casos covid 19'!K:K,"si",'Dataset - Casos covid 19'!D:D,"Buenos Aires") -> 76 | I3: =IF(H3=0,"No hay fallecidos",H3/E3) -> 0.14872798 | J3: =SUM(COUNTIFS('Dataset - Casos covid 19'!I:I,"descartado",'Dataset - Casos covid 19'!D:D,"Buenos Aires"),COUNTIFS('Dataset - Casos covid 19'!I:I,"sospechoso",'Dataset - Casos covid 19'!D:D,"Buenos Aires")) -> 171
A4: C) | B4: Cuántos fallecidos hubo en total? Cuántos casos confirmados en total? | D4: CABA | E4: =COUNTIFS('Dataset - Casos covid 19'!I:I,"confirmado",'Dataset - Casos covid 19'!D:D,"CABA") -> 1099 | F4: =COUNTIFS('Dataset - Casos covid 19'!I:I,"descartado",'Dataset - Casos covid 19'!D:D,"CABA") -> 185 | G4: =COUNTIFS('Dataset - Casos covid 19'!I:I,"sospechoso",'Dataset - Casos covid 19'!D:D,"CABA") -> 7 | H4: =COUNTIFS('Dataset - Casos covid 19'!K:K,"si",'Dataset - Casos covid 19'!D:D,"CABA") -> 240 | I4: =IF(H4=0,"No hay fallecidos",H4/E4) -> 0.21838035 | J4: =SUM(COUNTIFS('Dataset - Casos covid 19'!I:I,"descartado",'Dataset - Casos covid 19'!D:D,"CABA"),COUNTIFS('Dataset - Casos covid 19'!I:I,"sospechoso",'Dataset - Casos covid 19'!D:D,"CABA")) -> 192
A5: D) | B5: Cómo evolucionaron los casos confirmados y fallecimientos a lo largo del tiempo? | D5: Chaco | E5: =COUNTIFS('Dataset - Casos covid 19'!I:I,"confirmado",'Dataset - Casos covid 19'!D:D,"Chaco") -> 4 | F5: =COUNTIFS('Dataset - Casos covid 19'!I:I,"descartado",'Dataset - Casos covid 19'!D:D,"Chaco") -> 1 | G5: =COUNTIFS('Dataset - Casos covid 19'!I:I,"sospechoso",'Dataset - Casos covid 19'!D:D,"Chaco") -> 0 | H5: =COUNTIFS('Dataset - Casos covid 19'!K:K,"si",'Dataset - Casos covid 19'!D:D,"Chaco") -> 0 | I5: =IF(H5=0,"No hay fallecidos",H5/E5) -> No hay fallecidos | J5: =SUM(COUNTIFS('Dataset - Casos covid 19'!I:I,"descartado",'Dataset - Casos covid 19'!D:D,"Chaco"),COUNTIFS('Dataset - Casos covid 19'!I:I,"sospechoso",'Dataset - Casos covid 19'!D:D,"Chaco")) -> 1
A6: E) | B6: Cuál es la letalidad por provincia? | D6: Chubut | E6: =COUNTIFS('Dataset - Casos covid 19'!I:I,"confirmado",'Dataset - Casos covid 19'!D:D,"Chubut") -> 1 | F6: =COUNTIFS('Dataset - Casos covid 19'!I:I,"descartado",'Dataset - Casos covid 19'!D:D,"Chubut") -> 1 | G6: =COUNTIFS('Dataset - Casos covid 19'!I:I,"sospechoso",'Dataset - Casos covid 19'!D:D,"Chubut") -> 0 | H6: =COUNTIFS('Dataset - Casos covid 19'!K:K,"si",'Dataset - Casos covid 19'!D:D,"Chubut") -> 0 | I6: =IF(H6=0,"No hay fallecidos",H6/E6) -> No hay fallecidos | J6: =SUM(COUNTIFS('Dataset - Casos covid 19'!I:I,"descartado",'Dataset - Casos covid 19'!D:D,"Chubut"),COUNTIFS('Dataset - Casos covid 19'!I:I,"sospechoso",'Dataset - Casos covid 19'!D:D,"Chubut")) -> 1
A7: F) | B7: Cuál es la cantidad de casos no peligrosos por provincia? | D7: Córdoba | E7: =COUNTIFS('Dataset - Casos covid 19'!I:I,"confirmado",'Dataset - Casos covid 19'!D:D,"Córdoba") -> 0 | F7: =COUNTIFS('Dataset - Casos covid 19'!I:I,"descartado",'Dataset - Casos covid 19'!D:D,"Córdoba") -> 4 | G7: =COUNTIFS('Dataset - Casos covid 19'!I:I,"sospechoso",'Dataset - Casos covid 19'!D:D,"Córdoba") -> 0 | H7: =COUNTIFS('Dataset - Casos covid 19'!K:K,"si",'Dataset - Casos covid 19'!D:D,"Córdoba") -> 0 | I7: =IF(H7=0,"No hay fallecidos",H7/E7) -> No hay fallecidos | J7: =SUM(COUNTIFS('Dataset - Casos covid 19'!I:I,"descartado",'Dataset - Casos covid 19'!D:D,"Cordoba"),COUNTIFS('Dataset - Casos covid 19'!I:I,"sospechoso",'Dataset - Casos covid 19'!D:D,"Cordoba")) -> 0
A8: G) | B8: Cuántos fallecidos hay en el AMBA? Cuantos no fallecidos? | D8: Corrientes | E8: =COUNTIFS('Dataset - Casos covid 19'!I:I,"confirmado",'Dataset - Casos covid 19'!D:D,"Corrientes") -> 0 | F8: =COUNTIFS('Dataset - Casos covid 19'!I:I,"descartado",'Dataset - Casos covid 19'!D:D,"Corrientes") -> 3 | G8: =COUNTIFS('Dataset - Casos covid 19'!I:I,"sospechoso",'Dataset - Casos covid 19'!D:D,"Corrientes") -> 0 | H8: =COUNTIFS('Dataset - Casos covid 19'!K:K,"si",'Dataset - Casos covid 19'!D:D,"Corrientes") -> 0 | I8: =IF(H8=0,"No hay fallecidos",H8/E8) -> No hay fallecidos | J8: =SUM(COUNTIFS('Dataset - Casos covid 19'!I:I,"descartado",'Dataset - Casos covid 19'!D:D,"Corrientes"),COUNTIFS('Dataset - Casos covid 19'!I:I,"sospechoso",'Dataset - Casos covid 19'!D:D,"Corrientes")) -> 3
D9: Formosa | E9: =COUNTIFS('Dataset - Casos covid 19'!I:I,"confirmado",'Dataset - Casos covid 19'!D:D,"Formosa") -> 0 | F9: =COUNTIFS('Dataset - Casos covid 19'!I:I,"descartado",'Dataset - Casos covid 19'!D:D,"Formosa") -> 1 | G9: =COUNTIFS('Dataset - Casos covid 19'!I:I,"sospechoso",'Dataset - Casos covid 19'!D:D,"Formosa") -> 0 | H9: =COUNTIFS('Dataset - Casos covid 19'!K:K,"si",'Dataset - Casos covid 19'!D:D,"Formosa") -> 0 | I9: =IF(H9=0,"No hay fallecidos",H9/E9) -> No hay fallecidos | J9: =SUM(COUNTIFS('Dataset - Casos covid 19'!I:I,"descartado",'Dataset - Casos covid 19'!D:D,"Formosa"),COUNTIFS('Dataset - Casos covid 19'!I:I,"sospechoso",'Dataset - Casos covid 19'!D:D,"Formosa")) -> 1
A10: Fórmulas: | D10: Jujuy | E10: =COUNTIFS('Dataset - Casos covid 19'!I:I,"confirmado",'Dataset - Casos covid 19'!D:D,"Jujuy") -> 0 | F10: =COUNTIFS('Dataset - Casos covid 19'!I:I,"descartado",'Dataset - Casos covid 19'!D:D,"Jujuy") -> 2 | G10: =COUNTIFS('Dataset - Casos covid 19'!I:I,"sospechoso",'Dataset - Casos covid 19'!D:D,"Jujuy") -> 0 | H10: =COUNTIFS('Dataset - Casos covid 19'!K:K,"si",'Dataset - Casos covid 19'!D:D,"Jujuy") -> 0 | I10: =IF(H10=0,"No hay fallecidos",H10/E10) -> No hay fallecidos | J10: =SUM(COUNTIFS('Dataset - Casos covid 19'!I:I,"descartado",'Dataset - Casos covid 19'!D:D,"Jujuy"),COUNTIFS('Dataset - Casos covid 19'!I:I,"sospechoso",'Dataset - Casos covid 19'!D:D,"Jujuy")) -> 2
A11: A) | B11: " =CONTAR.SI.CONJUNTO('Dataset - Casos covid 19'!I:I;"confirmado";'Dataset - Casos covid 19'!D:D;"provincia")" | D11: La Rioja | E11: =COUNTIFS('Dataset - Casos covid 19'!I:I,"confirmado",'Dataset - Casos covid 19'!D:D,"La Rioja") -> 2 | F11: =COUNTIFS('Dataset - Casos covid 19'!I:I,"descartado",'Dataset - Casos covid 19'!D:D,"La Rioja") -> 0 | G11: =COUNTIFS('Dataset - Casos covid 19'!I:I,"sospechoso",'Dataset - Casos covid 19'!D:D,"La Rioja") -> 0 | H11: =COUNTIFS('Dataset - Casos covid 19'!K:K,"si",'Dataset - Casos covid 19'!D:D,"La Rioja") -> 1 | I11: =IF(H11=0,"No hay fallecidos",H11/E11) -> 0.5 | J11: =SUM(COUNTIFS('Dataset - Casos covid 19'!I:I,"descartado",'Dataset - Casos covid 19'!D:D,"La Rioja"),COUNTIFS('Dataset - Casos covid 19'!I:I,"sospechoso",'Dataset - Casos covid 19'!D:D,"La Rioja")) -> 0
A12: A) | B12: "=MAX(F3:F18)" y "=BUSCARX(E21;E3:E18;D3:D18;"";0;1)" | D12: Mendoza | E12: =COUNTIFS('Dataset - Casos covid 19'!I:I,"confirmado",'Dataset - Casos covid 19'!D:D,"Mendoza") -> 0 | F12: =COUNTIFS('Dataset - Casos covid 19'!I:I,"descartado",'Dataset - Casos covid 19'!D:D,"Mendoza") -> 1 | G12: =COUNTIFS('Dataset - Casos covid 19'!I:I,"sospechoso",'Dataset - Casos covid 19'!D:D,"Mendoza") -> 0 | H12: =COUNTIFS('Dataset - Casos covid 19'!K:K,"si",'Dataset - Casos covid 19'!D:D,"Mendoza") -> 0 | I12: =IF(H12=0,"No hay fallecidos",H12/E12) -> No hay fallecidos | J12: =SUM(COUNTIFS('Dataset - Casos covid 19'!I:I,"descartado",'Dataset - Casos covid 19'!D:D,"Mendoza"),COUNTIFS('Dataset - Casos covid 19'!I:I,"sospechoso",'Dataset - Casos covid 19'!D:D,"Mendoza")) -> 1
A13: A) | B13: "=BUSCARX(E21;E3:E18;D3:D18;"";0;1)" | D13: Misiones | E13: =COUNTIFS('Dataset - Casos covid 19'!I:I,"confirmado",'Dataset - Casos covid 19'!D:D,"Misiones") -> 0 | F13: =COUNTIFS('Dataset - Casos covid 19'!I:I,"descartado",'Dataset - Casos covid 19'!D:D,"Misiones") -> 3 | G13: =COUNTIFS('Dataset - Casos covid 19'!I:I,"sospechoso",'Dataset - Casos covid 19'!D:D,"Misiones") -> 0 | H13: =COUNTIFS('Dataset - Casos covid 19'!K:K,"si",'Dataset - Casos covid 19'!D:D,"Misiones") -> 0 | I13: =IF(H13=0,"No hay fallecidos",H13/E13) -> No hay fallecidos | J13: =SUM(COUNTIFS('Dataset - Casos covid 19'!I:I,"descartado",'Dataset - Casos covid 19'!D:D,"Misiones"),COUNTIFS('Dataset - Casos covid 19'!I:I,"sospechoso",'Dataset - Casos covid 19'!D:D,"Misiones")) -> 3
A14: A) | B14: "=MAX(E3:E18)" | D14: Río Negro | E14: =COUNTIFS('Dataset - Casos covid 19'!I:I,"confirmado",'Dataset - Casos covid 19'!D:D,"Río Negro") -> 1 | F14: =COUNTIFS('Dataset - Casos covid 19'!I:I,"descartado",'Dataset - Casos covid 19'!D:D,"Río Negro") -> 0 | G14: =COUNTIFS('Dataset - Casos covid 19'!I:I,"sospechoso",'Dataset - Casos covid 19'!D:D,"Río Negro") -> 0 | H14: =COUNTIFS('Dataset - Casos covid 19'!K:K,"si",'Dataset - Casos covid 19'!D:D,"Río Negro") -> 0 | I14: =IF(H14=0,"No hay fallecidos",H14/E14) -> No hay fallecidos | J14: =SUM(COUNTIFS('Dataset - Casos covid 19'!I:I,"descartado",'Dataset - Casos covid 19'!D:D,"Rio Negro"),COUNTIFS('Dataset - Casos covid 19'!I:I,"sospechoso",'Dataset - Casos covid 19'!D:D,"Rio Negro")) -> 0
D15: Salta | E15: =COUNTIFS('Dataset - Casos covid 19'!I:I,"confirmado",'Dataset - Casos covid 19'!D:D,"Salta") -> 0 | F15: =COUNTIFS('Dataset - Casos covid 19'!I:I,"descartado",'Dataset - Casos covid 19'!D:D,"Salta") -> 2 | G15: =COUNTIFS('Dataset - Casos covid 19'!I:I,"sospechoso",'Dataset - Casos covid 19'!D:D,"Salta") -> 0 | H15: =COUNTIFS('Dataset - Casos covid 19'!K:K,"si",'Dataset - Casos covid 19'!D:D,"Salta") -> 0 | I15: =IF(H15=0,"No hay fallecidos",H15/E15) -> No hay fallecidos | J15: =SUM(COUNTIFS('Dataset - Casos covid 19'!I:I,"descartado",'Dataset - Casos covid 19'!D:D,"Salta"),COUNTIFS('Dataset - Casos covid 19'!I:I,"sospechoso",'Dataset - Casos covid 19'!D:D,"Salta")) -> 2
A16: B) | B16: "=CONTAR.SI.CONJUNTO('Dataset - Casos covid 19'!K:K;"si";'Dataset - Casos covid 19'!D:D;"provincia")" | D16: San Juan | E16: =COUNTIFS('Dataset - Casos covid 19'!I:I,"confirmado",'Dataset - Casos covid 19'!D:D,"San Juan") -> 1 | F16: =COUNTIFS('Dataset - Casos covid 19'!I:I,"descartado",'Dataset - Casos covid 19'!D:D,"San Juan") -> 0 | G16: =COUNTIFS('Dataset - Casos covid 19'!I:I,"sospechoso",'Dataset - Casos covid 19'!D:D,"San Juan") -> 0 | H16: =COUNTIFS('Dataset - Casos covid 19'!K:K,"si",'Dataset - Casos covid 19'!D:D,"San Juan") -> 0 | I16: =IF(H16=0,"No hay fallecidos",H16/E16) -> No hay fallecidos | J16: =SUM(COUNTIFS('Dataset - Casos covid 19'!I:I,"descartado",'Dataset - Casos covid 19'!D:D,"San Juan"),COUNTIFS('Dataset - Casos covid 19'!I:I,"sospechoso",'Dataset - Casos covid 19'!D:D,"San Juan")) -> 0
A17: B) | B17: "=CONTAR.SI.CONJUNTO('Dataset - Casos covid 19'!I:I;"sospechoso";'Dataset - Casos covid 19'!D:D;"provincia")" | D17: San Luis | E17: =COUNTIFS('Dataset - Casos covid 19'!I:I,"confirmado",'Dataset - Casos covid 19'!D:D,"San Luis") -> 1 | F17: =COUNTIFS('Dataset - Casos covid 19'!I:I,"descartado",'Dataset - Casos covid 19'!D:D,"San Luis") -> 0 | G17: =COUNTIFS('Dataset - Casos covid 19'!I:I,"sospechoso",'Dataset - Casos covid 19'!D:D,"San Luis") -> 0 | H17: =COUNTIFS('Dataset - Casos covid 19'!K:K,"si",'Dataset - Casos covid 19'!D:D,"San Luis") -> 0 | I17: =IF(H17=0,"No hay fallecidos",H17/E17) -> No hay fallecidos | J17: =SUM(COUNTIFS('Dataset - Casos covid 19'!I:I,"descartado",'Dataset - Casos covid 19'!D:D,"San Luis"),COUNTIFS('Dataset - Casos covid 19'!I:I,"sospechoso",'Dataset - Casos covid 19'!D:D,"San Luis")) -> 0
A18: B) | B18: "=CONTAR.SI.CONJUNTO('Dataset - Casos covid 19'!I:I;"descartado";'Dataset - Casos covid 19'!D:D;"provincia")" | D18: Tucumán | E18: =COUNTIFS('Dataset - Casos covid 19'!I:I,"confirmado",'Dataset - Casos covid 19'!D:D,"Tucumán") -> 1 | F18: =COUNTIFS('Dataset - Casos covid 19'!I:I,"descartado",'Dataset - Casos covid 19'!D:D,"Tucumán") -> 1 | G18: =COUNTIFS('Dataset - Casos covid 19'!I:I,"sospechoso",'Dataset - Casos covid 19'!D:D,"Tucumán") -> 0 | H18: =COUNTIFS('Dataset - Casos covid 19'!K:K,"si",'Dataset - Casos covid 19'!D:D,"Tucumán") -> 0 | I18: =IF(H18=0,"No hay fallecidos",H18/E18) -> No hay fallecidos | J18: =SUM(COUNTIFS('Dataset - Casos covid 19'!I:I,"descartado",'Dataset - Casos covid 19'!D:D,"Tucumán"),COUNTIFS('Dataset - Casos covid 19'!I:I,"sospechoso",'Dataset - Casos covid 19'!D:D,"Tucumán")) -> 1
A20: C) | B20: "=SUMA(F3:F18)"
A21: C) | B21: "=SUMA(E3:E18)" | D21: A) Provincia con más casos confirmados | G21: C) Cantidad de fallecidos total | J21: F) Cantidad de fallecidos en AMBA
D22: =_xlfn.XLOOKUP(E22,E3:E24,D3:D24,"",0,1) -> CABA | E22: =MAX(E3:E24) -> 1099 | G22: =SUM(H3:H24) -> 317 | J22: =SUM(COUNTIFS('Dataset - Casos covid 19'!K:K,"si",'Dataset - Casos covid 19'!D:D,"CABA"), COUNTIFS('Dataset - Casos covid 19'!K:K,"si",'Dataset - Casos covid 19'!D:D,"Buenos Aires")) -> 316
A23: E) | B23: "=SI(H3=0;"No hay fallecidos";H3/E3)"
J24: Cantidad de no fallecidos en AMBA
D25: A) Provincia con más fallecidos | G25: C) Cantidad de casos confirmados total | J25: =SUM(COUNTIFS('Dataset - Casos covid 19'!K:K,"no",'Dataset - Casos covid 19'!D:D,"CABA"), COUNTIFS('Dataset - Casos covid 19'!K:K,"no",'Dataset - Casos covid 19'!D:D,"Buenos Aires")) -> 1657
D26: =_xlfn.XLOOKUP(E26,H3:H24,D3:D24,"",0,1) -> CABA | E26: =MAX(H3:H24) -> 240 | G26: =SUM(E3:E24) -> 1621
D29: Mes | E29: Cantidad de casos confirmados | F29: Cantidad de fallecidos
D30: 43831 | E30: =COUNTIFS('Dataset - Casos covid 19'!B:B,">=01/01/2020",'Dataset - Casos covid 19'!B:B,"<=31/01/2020",'Dataset - Casos covid 19'!I:I,"confirmado") -> 0 | F30: =COUNTIFS('Dataset - Casos covid 19'!B:B,">=01/01/2020",'Dataset - Casos covid 19'!B:B,"<=31/01/2020",'Dataset - Casos covid 19'!K:K,"si") -> 0
D31: 43862 | E31: =COUNTIFS('Dataset - Casos covid 19'!B:B,">=01/02/2020",'Dataset - Casos covid 19'!B:B,"<=28/02/2020",'Dataset - Casos covid 19'!I:I,"confirmado") -> 0 | F31: =COUNTIFS('Dataset - Casos covid 19'!B:B,">=01/02/2020",'Dataset - Casos covid 19'!B:B,"<=28/02/2020",'Dataset - Casos covid 19'!K:K,"si") -> 0
D32: 43891 | E32: =COUNTIFS('Dataset - Casos covid 19'!B:B,">=01/03/2020",'Dataset - Casos covid 19'!B:B,"<=31/03/2020",'Dataset - Casos covid 19'!I:I,"confirmado") -> 2 | F32: =COUNTIFS('Dataset - Casos covid 19'!B:B,">=01/03/2020",'Dataset - Casos covid 19'!B:B,"<=31/03/2020",'Dataset - Casos covid 19'!K:K,"si") -> 2
D33: 43922 | E33: =COUNTIFS('Dataset - Casos covid 19'!B:B,">=01/04/2020",'Dataset - Casos covid 19'!B:B,"<=30/04/2020",'Dataset - Casos covid 19'!I:I,"confirmado") -> 8 | F33: =COUNTIFS('Dataset - Casos covid 19'!B:B,">=01/04/2020",'Dataset - Casos covid 19'!B:B,"<=30/04/2020",'Dataset - Casos covid 19'!K:K,"si") -> 6
D34: 43952 | E34: =COUNTIFS('Dataset - Casos covid 19'!B:B,">=01/05/2020",'Dataset - Casos covid 19'!B:B,"<=31/05/2020",'Dataset - Casos covid 19'!I:I,"confirmado") -> 21 | F34: =COUNTIFS('Dataset - Casos covid 19'!B:B,">=01/05/2020",'Dataset - Casos covid 19'!B:B,"<=31/05/2020",'Dataset - Casos covid 19'!K:K,"si") -> 11
D35: 43983 | E35: =COUNTIFS('Dataset - Casos covid 19'!B:B,">=01/06/2020",'Dataset - Casos covid 19'!B:B,"<=30/06/2020",'Dataset - Casos covid 19'!I:I,"confirmado") -> 64 | F35: =COUNTIFS('Dataset - Casos covid 19'!B:B,">=01/06/2020",'Dataset - Casos covid 19'!B:B,"<=30/06/2020",'Dataset - Casos covid 19'!K:K,"si") -> 36
D36: 44013 | E36: =COUNTIFS('Dataset - Casos covid 19'!B:B,">=01/07/2020",'Dataset - Casos covid 19'!B:B,"<=31/07/2020",'Dataset - Casos covid 19'!I:I,"confirmado") -> 442 | F36: =COUNTIFS('Dataset - Casos covid 19'!B:B,">=01/07/2020",'Dataset - Casos covid 19'!B:B,"<=31/07/2020",'Dataset - Casos covid 19'!K:K,"si") -> 78
D37: 44044 | E37: =COUNTIFS('Dataset - Casos covid 19'!B:B,">=01/08/2020",'Dataset - Casos covid 19'!B:B,"<=31/08/2020",'Dataset - Casos covid 19'!I:I,"confirmado") -> 428 | F37: =COUNTIFS('Dataset - Casos covid 19'!B:B,">=01/08/2020",'Dataset - Casos covid 19'!B:B,"<=31/08/2020",'Dataset - Casos covid 19'!K:K,"si") -> 69
D38: 44075 | E38: =COUNTIFS('Dataset - Casos covid 19'!B:B,">=01/9/2020",'Dataset - Casos covid 19'!B:B,"<=30/9/2020",'Dataset - Casos covid 19'!I:I,"confirmado") -> 489 | F38: =COUNTIFS('Dataset - Casos covid 19'!B:B,">=01/9/2020",'Dataset - Casos covid 19'!B:B,"<=30/9/2020",'Dataset - Casos covid 19'!K:K,"si") -> 50
D39: 44105 | E39: =COUNTIFS('Dataset - Casos covid 19'!B:B,">=01/10/2020",'Dataset - Casos covid 19'!B:B,"<=31/10/2020",'Dataset - Casos covid 19'!I:I,"confirmado") -> 69 | F39: =COUNTIFS('Dataset - Casos covid 19'!B:B,">=01/10/2020",'Dataset - Casos covid 19'!B:B,"<=31/10/2020",'Dataset - Casos covid 19'!K:K,"si") -> 28
D40: 44136 | E40: =COUNTIFS('Dataset - Casos covid 19'!B:B,">=01/11/2020",'Dataset - Casos covid 19'!B:B,"<=30/11/2020",'Dataset - Casos covid 19'!I:I,"confirmado") -> 43 | F40: =COUNTIFS('Dataset - Casos covid 19'!B:B,">=01/11/2020",'Dataset - Casos covid 19'!B:B,"<=30/11/2020",'Dataset - Casos covid 19'!K:K,"si") -> 17
D41: 44166 | E41: =COUNTIFS('Dataset - Casos covid 19'!B:B,">=01/12/2020",'Dataset - Casos covid 19'!B:B,"<=31/12/2020",'Dataset - Casos covid 19'!I:I,"confirmado") -> 47 | F41: =COUNTIFS('Dataset - Casos covid 19'!B:B,">=01/12/2020",'Dataset - Casos covid 19'!B:B,"<=31/12/2020",'Dataset - Casos covid 19'!K:K,"si") -> 18
D42: 44197 | E42: =COUNTIFS('Dataset - Casos covid 19'!B:B,">=01/01/2021",'Dataset - Casos covid 19'!B:B,"<=31/01/2021",'Dataset - Casos covid 19'!I:I,"confirmado") -> 4 | F42: =COUNTIFS('Dataset - Casos covid 19'!B:B,">=01/01/2021",'Dataset - Casos covid 19'!B:B,"<=31/01/2021",'Dataset - Casos covid 19'!K:K,"si") -> 0
D43: 44228 | E43: =COUNTIFS('Dataset - Casos covid 19'!B:B,">=01/02/2021",'Dataset - Casos covid 19'!B:B,"<=28/02/2021",'Dataset - Casos covid 19'!I:I,"confirmado") -> 0 | F43: =COUNTIFS('Dataset - Casos covid 19'!B:B,">=01/02/2021",'Dataset - Casos covid 19'!B:B,"<=28/02/2021",'Dataset - Casos covid 19'!K:K,"si") -> 0
...

Sheet Dataset - Casos covid 19
A1: Numero de caso | B1: Fecha toma muestra | C1: Fecha clasificacion | D1: Provincia | E1: Barrio | F1: Comuna | G1: Genero | H1: Edad | I1: Clasificacion | J1: Fecha de fallecimiento | K1: Fallecido | L1: Fecha de alta | M1: Tipo de contagio
A2: 1723045 | B2: 44048 | C2: 44049 | D2: CABA | E2: CHACARITA | F2: 15 | G2: femenino | H2: 60 | I2: confirmado | J2: 44084 | K2: si | M2: Comunitario
A3: 2399359 | B3: 44080 | C3: 44080 | D3: Buenos Aires | E3: BERAZATEGUI | G3: masculino | H3: 78 | I3: confirmado | J3: 44087 | K3: si | M3: Comunitario
A4: 1060680 | B4: 43993 | C4: 43993 | D4: CABA | E4: BALVANERA | F4: 3 | G4: masculino | H4: 59 | I4: confirmado | J4: 44050 | K4: si | M4: Comunitario
A5: 2145842 | B5: 44069 | C5: 44070 | D5: CABA | E5: COLEGIALES | F5: 13 | G5: masculino | H5: 63 | I5: confirmado | J5: 44086 | K5: si | M5: Comunitario
A6: 1194644 | B6: 44022 | C6: 44022 | D6: CABA | E6: FLORES | F6: 7 | G6: masculino | H6: 83 | I6: confirmado | J6: 44024 | K6: si | M6: Comunitario
A7: 1054863 | B7: 43992 | C7: 43993 | D7: CABA | E7: FLORES | F7: 7 | G7: femenino | H7: 83 | I7: confirmado | J7: 44000 | K7: si | M7: Contacto
A8: 2546740 | B8: 44085 | C8: 44086 | D8: Buenos Aires | E8: CAMPANA | G8: masculino | H8: 65 | I8: confirmado | J8: 44095 | K8: si | M8: Comunitario
A9: 1516977 | B9: 44036 | C9: 44036 | D9: CABA | E9: ALMAGRO | F9: 5 | G9: femenino | H9: 85 | I9: confirmado | J9: 44037 | K9: si | M9: Comunitario
A10: 2146461 | B10: 44078 | C10: 44083 | D10: CABA | E10: CABALLITO | F10: 6 | G10: femenino | H10: 77 | I10: confirmado | J10: 44092 | K10: si | M10: Comunitario
A11: 1780895 | B11: 44052 | C11: 44053 | D11: CABA | E11: MONSERRAT | F11: 1 | G11: masculino | H11: 79 | I11: confirmado | J11: 44109 | K11: si | M11: Comunitario
A12: 1326323 | B12: 44023 | C12: 44023 | D12: Buenos Aires | E12: LANUS | G12: masculino | H12: 84 | I12: confirmado | J12: 44032 | K12: si | M12: Comunitario
A13: 1084184 | B13: 43997 | C13: 43997 | D13: CABA | E13: RECOLETA | F13: 2 | G13: femenino | H13: 91 | I13: confirmado | J13: 44000 | K13: si | M13: Comunitario
A14: 2150392 | B14: 44063 | C14: 44063 | D14: CABA | E14: PALERMO | F14: 14 | G14: masculino | H14: 66 | I14: confirmado | J14: 44096 | K14: si | M14: Comunitario
A15: 4995210 | B15: 44146 | C15: 44147 | D15: Buenos Aires | E15: LOMAS DE ZAMORA | G15: femenino | H15: 64 | I15: confirmado | J15: 44161 | K15: si | M15: Comunitario
A16: 976322 | B16: 43961 | C16: 43961 | D16: CABA | E16: CABALLITO | F16: 6 | G16: femenino | H16: 92 | I16: descartado | K16: no
A17: 2800578 | B17: 44096 | C17: 44096 | D17: Buenos Aires | E17: LA PLATA | G17: masculino | H17: 86 | I17: confirmado | J17: 44110 | K17: si | M17: Comunitario
A18: 3860158 | B18: 44160 | C18: 44161 | D18: CABA | E18: VILLA CRESPO | F18: 15 | G18: femenino | H18: 84 | I18: confirmado | J18: 44175 | K18: si | M18: Contacto
A19: 1451243 | B19: 44032 | C19: 44033 | D19: CABA | E19: RECOLETA | F19: 2 | G19: masculino | H19: 82 | I19: confirmado | J19: 44037 | K19: si | M19: Comunitario
A20: 1381824 | B20: 44027 | C20: 44029 | D20: CABA | E20: PALERMO | F20: 14 | G20: masculino | H20: 82 | I20: confirmado | J20: 44044 | K20: si | M20: Comunitario
A21: 1349872 | B21: 44025 | C21: 44026 | D21: CABA | E21: RECOLETA | F21: 2 | G21: masculino | H21: 67 | I21: confirmado | J21: 44025 | K21: si | M21: Comunitario
A22: 935654 | B22: 43969 | C22: 43969 | D22: CABA | E22: BALVANERA | F22: 3 | G22: masculino | H22: 84 | I22: descartado | K22: no
A23: 1632320 | B23: 44040 | C23: 44041 | D23: CABA | E23: CONSTITUCION | F23: 1 | G23: femenino | H23: 95 | I23: confirmado | J23: 44056 | K23: si | M23: Contacto
A24: 2981190 | B24: 44102 | C24: 44103 | D24: Buenos Aires | E24: ALMIRANTE BROWN | G24: femenino | H24: 53 | I24: confirmado | J24: 44124 | K24: si | M24: Comunitario
A25: 1793396 | B25: 44053 | C25: 44054 | D25: CABA | E25: FLORES | F25: 7 | G25: femenino | H25: 74 | I25: confirmado | J25: 44057 | K25: si | M25: Comunitario
A26: 2478476 | B26: 44082 | C26: 44083 | D26: CABA | E26: PALERMO | F26: 14 | G26: masculino | H26: 70 | I26: confirmado | J26: 44103 | K26: si | M26: Comunitario
A27: 900942 | B27: 44022 | C27: 44022 | D27: CABA | E27: VILLA LUGANO | F27: 8 | G27: masculino | H27: 66 | I27: confirmado | J27: 44060 | K27: si | M27: Comunitario
A28: 4404251 | B28: 44148 | C28: 44149 | D28: CABA | E28: AGRONOMIA | F28: 15 | G28: femenino | H28: 84 | I28: confirmado | J28: 44155 | K28: si | M28: Comunitario
A29: 2525060 | B29: 44090 | C29: 44090 | D29: Buenos Aires | E29: MALVINAS ARGENTINAS | G29: femenino | H29: 73 | I29: confirmado | J29: 44092 | K29: si | M29: En Investigación
A30: 5131042 | B30: 44176 | C30: 44176 | D30: Buenos Aires | E30: SAN MIGUEL | G30: femenino | H30: 84 | I30: sospechoso | K30: no | M30: En Investigación
A31: 870294 | B31: 43949 | C31: 43950 | D31: Buenos Aires | E31: TIGRE | G31: femenino | H31: 88 | I31: confirmado | J31: 43947 | K31: si | M31: Comunitario
A32: 3196861 | B32: 44111 | C32: 44111 | D32: CABA | E32: BALVANERA | F32: 3 | G32: masculino | H32: 91 | I32: confirmado | J32: 44114 | K32: si | M32: Comunitario
A33: 1150538 | B33: 44004 | C33: 44005 | D33: CABA | E33: CABALLITO | F33: 6 | G33: femenino | H33: 80 | I33: confirmado | J33: 44019 | K33: si | M33: Trabajador de la Salud
A34: 1772044 | B34: 44046 | C34: 44047 | D34: CABA | E34: VERSALLES | F34: 10 | G34: masculino | H34: 80 | I34: confirmado | J34: 44050 | K34: si | M34: Comunitario
A35: 1103204 | B35: 43999 | C35: 43999 | D35: CABA | E35: PARQUE AVELLANEDA | F35: 9 | G35: femenino | H35: 56 | I35: descartado | K35: no
A36: 3086141 | B36: 44105 | C36: 44108 | D36: CABA | E36: PARQUE AVELLANEDA | F36: 9 | G36: masculino | H36: 71 | I36: confirmado | J36: 44126 | K36: si | M36: Comunitario
A37: 2073770 | B37: 44062 | C37: 44062 | D37: CABA | E37: COLEGIALES | F37: 13 | G37: masculino | H37: 63 | I37: confirmado | J37: 44095 | K37: si | M37: Comunitario
A38: 2361706 | B38: 44077 | C38: 44079 | D38: CABA | E38: PARQUE PATRICIOS | F38: 4 | G38: masculino | H38: 62 | I38: confirmado | J38: 44103 | K38: si | M38: En Investigación
A39: 1054950 | B39: 44006 | C39: 44008 | D39: CABA | E39: BALVANERA | F39: 3 | G39: femenino | H39: 88 | I39: confirmado | J39: 44038 | K39: si | M39: Comunitario
A40: 833697 | B40: 43939 | C40: 43944 | D40: CABA | E40: FLORES | F40: 7 | G40: femenino | H40: 94 | I40: confirmado | J40: 43952 | K40: si | M40: Contacto
...

Sheet Tablas dinamicas
A1: Recuento de Numero de casos | B1: Etiquetas de columna
A2: Etiquetas de fila | B2: confirmado | C2: descartado | D2: sospechoso | E2: Total general | H2: =IFERROR(GETPIVOTDATA("Numero de caso",$A$1,"Clasificacion","confirmado"),"0") -> 1621 | I2: "=SI.ERROR(IMPORTARDATOSDINAMICOS("Numero de caso";$A$1;"Clasificacion";"confirmado");"0")"
A3: femenino | B3: 777 | C3: 184 | D3: 13 | E3: 974 | H3: =IFERROR(GETPIVOTDATA("Numero de caso",$A$1,"Clasificacion","descartado"),"0") -> 360 | I3: "=SI.ERROR(IMPORTARDATOSDINAMICOS("Numero de caso";$A$1;"Clasificacion";"descartado");"0")"
A4: masculino | B4: 844 | C4: 176 | D4: 9 | E4: 1029 | H4: =IFERROR(GETPIVOTDATA("Numero de caso",$A$1,"Clasificacion","sospechoso"),"0") -> 22 | I4: "=SI.ERROR(IMPORTARDATOSDINAMICOS("Numero de caso";$A$1;"Clasificacion";"sospechoso");"0")"
A5: Total general | B5: 1621 | C5: 360 | D5: 22 | E5: 2003 | I5: "=SI.ERROR(IMPORTARDATOSDINAMICOS("Numero de caso";$A$1;"Clasificacion";"confirmado");"0")"
I8: estas formulas estan para que no muestre un error de referencia en el dashboard, en caso de que no encuentre datos, que arroje "0"
G22: Cuenta de Numero de caso | H22: Etiquetas de columna
G23: Etiquetas de fila | H23: no | I23: si | J23: Total general | L23: Cantidad fallecidos | M23: Cantidad total | N23: Tasa letalidad
G24: Buenos Aires | H24: 606 | I24: 76 | J24: 682 | L24: =IFERROR(GETPIVOTDATA("Numero de caso", $G$23, "Fallecido", "si"),"0") -> 317 | M24: =GETPIVOTDATA("Numero de caso", $G$23) -> 2003 | N24: =IF(L24="0", "No hay fallecidos", L24/M24) -> 0.15826261
G25: CABA | H25: 1051 | I25: 240 | J25: 1291
G26: Chaco | H26: 5 | J26: 5
G27: Chubut | H27: 2 | J27: 2
G28: Córdoba | H28: 4 | J28: 4
G29: Corrientes | H29: 3 | J29: 3
G30: Formosa | H30: 1 | J30: 1
G31: Jujuy | H31: 2 | J31: 2
G32: La Rioja | H32: 1 | I32: 1 | J32: 2
G33: Mendoza | H33: 1 | J33: 1
G34: Misiones | H34: 3 | J34: 3
G35: Río Negro | H35: 1 | J35: 1
G36: Salta | H36: 2 | J36: 2
G37: San Juan | H37: 1 | J37: 1
G38: San Luis | H38: 1 | J38: 1
G39: Tucumán | H39: 2 | J39: 2
G40: Total general | H40: 1686 | I40: 317 | J40: 2003
G44: Etiquetas de fila | H44: Cuenta de Numero de caso
G45: Buenos Aires | H45: 682 | M45: Cuenta de Numero de caso | N45: Etiquetas de columna
G46: CABA | H46: 1291 | M46: Etiquetas de fila | N46: no | O46: si | P46: Total general
G47: Chaco | H47: 5 | M47: 2020 | N47: 1678 | O47: 312 | P47: 1990
G48: Chubut | H48: 2 | M48: ene | N48: 1 | P48: 1
G49: Córdoba | H49: 4 | M49: mar | N49: 3 | O49: 1 | P49: 4
G50: Corrientes | H50: 3 | M50: abr | N50: 17 | O50: 7 | P50: 24
G51: Formosa | H51: 1 | M51: may | N51: 27 | O51: 8 | P51: 35
G52: Jujuy | H52: 2 | M52: jun | N52: 48 | O52: 34 | P52: 82
G53: La Rioja | H53: 2 | M53: jul | N53: 408 | O53: 82 | P53: 490
G54: Mendoza | H54: 1 | M54: ago | N54: 379 | O54: 69 | P54: 448
G55: Misiones | H55: 3 | M55: sept | N55: 493 | O55: 49 | P55: 542
G56: Río Negro | H56: 1 | M56: oct | N56: 104 | O56: 28 | P56: 132
G57: Salta | H57: 2 | M57: nov | N57: 89 | O57: 17 | P57: 106
G58: San Juan | H58: 1 | M58: dic | N58: 109 | O58: 17 | P58: 126
...

Sheet Dataset original
A1: Numero de caso,"Fecha toma muestra","Fecha clasificacion","Provincia","Barrio","Comuna","Genero","Edad","Clasificacion","Fecha de fallecimiento","Fallecido","Fecha de alta","Tipo de contagio"
A2: 1723045,"8/5/2020","8/6/2020","CABA","CHACARITA","15","femenino","60","confirmado","9/10/2020","si","","Comunitario"
A3: 2399359,"9/6/2020","9/6/2020","Buenos Aires","BERAZATEGUI","","masculino","78","confirmado","9/13/2020","si","","Comunitario"
A4: 1060680,"6/11/2020","6/11/2020","CABA","BALVANERA","3","masculino","59","confirmado","8/7/2020","si","","Comunitario"
A5: 2145842,"8/26/2020","8/27/2020","CABA","COLEGIALES","13","masculino","63","confirmado","9/12/2020","si","","Comunitario"
A6: 1194644,"7/10/2020","7/10/2020","CABA","FLORES","7","masculino","83","confirmado","7/12/2020","si","","Comunitario"
A7: 1054863,"6/10/2020","6/11/2020","CABA","FLORES","7","femenino","83","confirmado","6/18/2020","si","","Contacto"
A8: 2546740,"9/11/2020","9/12/2020","Buenos Aires","CAMPANA","","masculino","65","confirmado","9/21/2020","si","","Comunitario"
A9: 1516977,"7/24/2020","7/24/2020","CABA","ALMAGRO","5","femenino","85","confirmado","7/25/2020","si","","Comunitario"
A10: 2146461,"9/4/2020","9/9/2020","CABA","CABALLITO","6","femenino","77","confirmado","9/18/2020","si","","Comunitario"
A11: 1780895,"8/9/2020","8/10/2020","CABA","MONSERRAT","1","masculino","79","confirmado","10/5/2020","si","","Comunitario"
A12: 1326323,"7/11/2020","7/11/2020","Buenos Aires","LANUS","","masculino","84","confirmado","7/20/2020","si","","Comunitario"
... A2004: 2008594,"8/20/2020","8/20/2020","CABA","MORON","4","masculino","3","confirmado","","no","","En InvestigaciÃ³n"

Sheet Hoja aux - validacion de datos
A1: Fallecido | C1: Clasificacion | E1: Genero | G1: Tipo de contagio | I1: Provincia
A2: si | C2: confirmado | E2: masculino | G2: Comunitario | I2: CABA
A3: no | C3: descartado | E3: femenino | G3: Contacto | I3: Buenos Aires
C4: sospechoso | G4: En Investigación | I4: Chaco
G5: Trabajador de la Salud | I5: Chubut
I6: Córdoba
I7: Corrientes
I8: Formosa
I9: Jujuy
I10: La Rioja
I11: Mendoza
I12: Misiones
I13: Río Negro
I14: Salta
I15: San Juan
I16: San Luis
I17: Tucumán
